Workbook

Sheet README
A1: United Airlines Holdings (UAL) — модель оценки
A3: Дата анализа: 14.10.2026. Цена акции: $103,23 — закрытие NASDAQ 13.10.2026 (Yahoo Finance chart API; совпадает с отчётом Zacks/Yahoo от 13.10.2026).
A4: Последняя опубликованная отчётность: 10-Q за 2 кв. 2026 (подан в SEC 16.07.2026) и 8-K с пресс-релизом от 15.07.2026.
A5: Отчёт за 3 кв. 2026 на дату анализа НЕ вышел: компания назначила публикацию на 20.10.2026 после закрытия рынка (звонок 21.10.2026). Данные 3 кв. в модели не используются.
A6: Пиры: TTM на 30.06.2026 (последний общий период для всех). Delta уже отчиталась за 3 кв. (09.10.2026), но для сопоставимости берём её данные на 30.06.2026.
A8: Цвета: синий шрифт — вводные значения (факты из отчётности и допущения); чёрный — формулы. Жёлтая заливка — ключевые результаты.
A9: Типы данных в колонке источника: [Ф] факт из отчётности; [Д] допущение аналитика; [О] оценка аналитика (расчёт на основе фактов).
A10: Все финансовые показатели — млн долл. США, если не указано иное. Удельные показатели (TRASM, CASM) — центы на ASM.
A12: Листы:
A13: Hist — исходные данные 2019–2025, 1П25, 1П26, TTM 2К26 и квартальные данные (факты с указанием документа SEC).
A14: Metrics — производные метрики (формулы): загрузка, доходность, маржи, качество прибыли, долговая нагрузка.
A15: Assumptions — ВСЕ допущения прогноза в одном месте: рынок, WACC, драйверы по трём сценариям, терминальные параметры, вероятности.
... A23: Debt — график погашения, ликвидность, рейтинги, сравнение долговой нагрузки через EBITDAR и через операционный денежный поток, поставки самолётов.

Sheet Hist
A1: Исходные данные UAL (факты из отчётности SEC)
A3: Показатель | B3: Ед. | C3: 2019 | D3: 2020 | E3: 2021 | F3: 2022 | G3: 2023 | H3: 2024 | I3: 2025 | J3: 1П25 | K3: 1П26 | L3: TTM 2К26 | M3: Источник / тип
A4: Операционные показатели
A5: Пассажиро-кресло-мили (ASM) | B5: млн | C5: 284999 | D5: 122804 | E5: 178684 | F5: 247858 | G5: 291333 | H5: 311185 | I5: 330284 | J5: 159503 | K5: 164977 | L5: =I5+K5-J5 -> 335758 | M5: [Ф] Пресс-релизы 8-K по итогам 4 кв.: FY2019–2021 (8-K 19.01.2022), FY2022 (17.01.2023), FY2023 (22.01.2024), FY2024 (21.01.2025), FY2025 (20.01.2026); 1П — 8-K 15.07.2026
A6: Пассажиро-мили (RPM) | B6: млн | C6: 239360 | D6: 73883 | E6: 128979 | F6: 206791 | G6: 244435 | H6: 258503 | I6: 271619 | J6: 129604 | K6: 136150 | L6: =I6+K6-J6 -> 278165 | M6: [Ф] Пресс-релизы 8-K по итогам 4 кв.: FY2019–2021 (8-K 19.01.2022), FY2022 (17.01.2023), FY2023 (22.01.2024), FY2024 (21.01.2025), FY2025 (20.01.2026); 1П — 8-K 15.07.2026
A7: Пассажиры | B7: тыс. | C7: 162443 | D7: 57761 | E7: 104082 | F7: 144300 | G7: 164927 | H7: 173603 | I7: 181053 | J7: 86992 | K7: 91178 | L7: =I7+K7-J7 -> 185239 | M7: [Ф] Пресс-релизы 8-K по итогам 4 кв.: FY2019–2021 (8-K 19.01.2022), FY2022 (17.01.2023), FY2023 (22.01.2024), FY2024 (21.01.2025), FY2025 (20.01.2026); 1П — 8-K 15.07.2026
A8: CASM-ex (отчётный, non-GAAP) | B8: центы | C8: 10.21 | D8: 17.13 | E8: 12.96 | F8: 11.73 | G8: 12.03 | H8: 12.58 | I8: 12.64 | J8: 12.74 | K8: 13.51 | M8: [Ф] Пресс-релизы 8-K по итогам 4 кв.: FY2019–2021 (8-K 19.01.2022), FY2022 (17.01.2023), FY2023 (22.01.2024), FY2024 (21.01.2025), FY2025 (20.01.2026); 1П — 8-K 15.07.2026; без топлива, участия в прибыли, спецстатей и сторонних услуг
A9: Средняя цена топлива | B9: $/галлон | C9: 2.09 | D9: 1.57 | E9: 2.11 | F9: 3.63 | G9: 3.01 | H9: 2.65 | I9: 2.44 | J9: 2.43 | K9: 3.53 | M9: [Ф] Пресс-релизы 8-K по итогам 4 кв.: FY2019–2021 (8-K 19.01.2022), FY2022 (17.01.2023), FY2023 (22.01.2024), FY2024 (21.01.2025), FY2025 (20.01.2026); 1П — 8-K 15.07.2026
A10: Потреблено топлива | B10: млн галл. | C10: 4292 | D10: 2004 | E10: 2729 | F10: 3608 | G10: 4205 | H10: 4444 | I10: 4663 | J10: 2254 | K10: 2312 | L10: =I10+K10-J10 -> 4721 | M10: [Ф] Пресс-релизы 8-K по итогам 4 кв.: FY2019–2021 (8-K 19.01.2022), FY2022 (17.01.2023), FY2023 (22.01.2024), FY2024 (21.01.2025), FY2025 (20.01.2026); 1П — 8-K 15.07.2026
A11: Самолётов в парке на конец периода | B11: шт. | C11: 1372 | D11: 1287 | E11: 1344 | F11: 1338 | G11: 1358 | H11: 1406 | I11: 1490 | J11: 1473 | K11: 1552 | L11: =K11 -> 1552 | M11: [Ф] Пресс-релизы 8-K по итогам 4 кв.: FY2019–2021 (8-K 19.01.2022), FY2022 (17.01.2023), FY2023 (22.01.2024), FY2024 (21.01.2025), FY2025 (20.01.2026); 1П — 8-K 15.07.2026
A12: Численность персонала на конец периода | B12: тыс. | C12: 95.9 | D12: 74.4 | E12: 84.1 | F12: 92.8 | G12: 103.3 | H12: 107.3 | I12: 113.2 | J12: 111.3 | K12: 117.5 | L12: =K12 -> 117.5 | M12: [Ф] Пресс-релизы 8-K по итогам 4 кв.: FY2019–2021 (8-K 19.01.2022), FY2022 (17.01.2023), FY2023 (22.01.2024), FY2024 (21.01.2025), FY2025 (20.01.2026); 1П — 8-K 15.07.2026
A13: Средняя длина рейса | B13: миль | C13: 1460 | D13: 1307 | E13: 1315 | F13: 1437 | G13: 1479 | H13: 1490 | I13: 1488 | J13: 1482 | K13: 1462 | M13: [Ф] Пресс-релизы 8-K по итогам 4 кв.: FY2019–2021 (8-K 19.01.2022), FY2022 (17.01.2023), FY2023 (22.01.2024), FY2024 (21.01.2025), FY2025 (20.01.2026); 1П — 8-K 15.07.2026
A14: Грузовые тонно-мили (RTM) | B14: млн | C14: 3329 | D14: 2711 | E14: 3285 | F14: 3041 | G14: 3159 | H14: 3604 | I14: 3626 | J14: 1774 | K14: 1810 | L14: =I14+K14-J14 -> 3662 | M14: [Ф] Пресс-релизы 8-K по итогам 4 кв.: FY2019–2021 (8-K 19.01.2022), FY2022 (17.01.2023), FY2023 (22.01.2024), FY2024 (21.01.2025), FY2025 (20.01.2026); 1П — 8-K 15.07.2026
A15: Отчёт о прибылях и убытках
A16: Пассажирская выручка | B16: $ млн | C16: 39625 | D16: 11805 | E16: 20197 | F16: 40032 | G16: 49046 | H16: 51829 | I16: 53438 | J16: 25696 | K16: 29267 | L16: =I16+K16-J16 -> 57009 | M16: [Ф] Пресс-релизы 8-K по итогам 4 кв.: FY2019–2021 (8-K 19.01.2022), FY2022 (17.01.2023), FY2023 (22.01.2024), FY2024 (21.01.2025), FY2025 (20.01.2026); 1П — 8-K 15.07.2026
A17: Грузовая выручка | B17: $ млн | C17: 1179 | D17: 1648 | E17: 2349 | F17: 2171 | G17: 1495 | H17: 1743 | I17: 1779 | J17: 859 | K17: 949 | L17: =I17+K17-J17 -> 1869 | M17: [Ф] Пресс-релизы 8-K по итогам 4 кв.: FY2019–2021 (8-K 19.01.2022), FY2022 (17.01.2023), FY2023 (22.01.2024), FY2024 (21.01.2025), FY2025 (20.01.2026); 1П — 8-K 15.07.2026; 10-K 2025 (Cargo 1,779/1,743)
A18: Прочая операционная выручка | B18: $ млн | C18: 2455 | D18: 1902 | E18: 2088 | F18: 2752 | G18: 3176 | H18: 3491 | I18: 3853 | J18: 1893 | K18: 2064 | L18: =I18+K18-J18 -> 4024 | M18: [Ф] Пресс-релизы 8-K по итогам 4 кв.: FY2019–2021 (8-K 19.01.2022), FY2022 (17.01.2023), FY2023 (22.01.2024), FY2024 (21.01.2025), FY2025 (20.01.2026); 1П — 8-K 15.07.2026
A19: Итого операционная выручка | B19: $ млн | C19: =SUM(C16:C18) -> 43259 | D19: =SUM(D16:D18) -> 15355 | E19: =SUM(E16:E18) -> 24634 | F19: =SUM(F16:F18) -> 44955 | G19: =SUM(G16:G18) -> 53717 | H19: =SUM(H16:H18) -> 57063 | I19: =SUM(I16:I18) -> 59070 | J19: =SUM(J16:J18) -> 28448 | ... L19: =SUM(L16:L18) -> 62902 | M19: формула; сверка с отчётной выручкой ниже
A20: Справочно: выручка по отчётности | B20: $ млн | C20: 43259 | D20: 15355 | E20: 24634 | F20: 44955 | G20: 53717 | H20: 57063 | I20: 59070 | J20: 28448 | K20: 32280 | L20: =I20+K20-J20 -> 62902 | M20: [Ф] XBRL RevenueFromContractWithCustomer (10-K/10-Q)
A21: в т.ч. выручка от партнёров MileagePlus в прочей выручке | B21: $ млн | G21: 2700 | H21: 2900 | I21: 3200 | J21: 1600 | K21: 1800 | L21: =I21+K21-J21 -> 3400 | M21: [Ф] 10-K 2025 прим. 2 ($3.2/2.9/2.7 млрд); 10-Q 2К26 ($1.8/1.6 млрд за 6 мес.). 2019–2022: не найдено в использованных документах
A22: Мили начислены (отложенная выручка, прирост) | B22: $ млн | H22: 3563 | I22: 3883 | M22: [Ф] 10-K 2025, roll-forward Frequent flyer deferred revenue
A23: Мили погашены на перелёты (признано в пасс. выручке) | B23: $ млн | H23: 3150 | I23: 3414 | M23: [Ф] 10-K 2025, roll-forward Frequent flyer deferred revenue
A24: Расходы на топливо | B24: $ млн | C24: 8953 | D24: 3153 | E24: 5755 | F24: 13113 | G24: 12651 | H24: 11756 | I24: 11396 | J24: 5476 | K24: 8150 | L24: =I24+K24-J24 -> 14070 | M24: [Ф] Пресс-релизы 8-K по итогам 4 кв.: FY2019–2021 (8-K 19.01.2022), FY2022 (17.01.2023), FY2023 (22.01.2024), FY2024 (21.01.2025), FY2025 (20.01.2026); 1П — 8-K 15.07.2026
A25: Зарплата и связанные расходы | B25: $ млн | C25: 12071 | D25: 9522 | E25: 9566 | F25: 11466 | G25: 14787 | H25: 16678 | I25: 17647 | J25: 8568 | K25: 9248 | L25: =I25+K25-J25 -> 18327 | M25: [Ф] Пресс-релизы 8-K по итогам 4 кв.: FY2019–2021 (8-K 19.01.2022), FY2022 (17.01.2023), FY2023 (22.01.2024), FY2024 (21.01.2025), FY2025 (20.01.2026); 1П — 8-K 15.07.2026
A26: Амортизация (D&A) | B26: $ млн | C26: 2288 | D26: 2488 | E26: 2485 | F26: 2456 | G26: 2671 | H26: 2928 | I26: 2939 | J26: 1461 | K26: 1518 | L26: =I26+K26-J26 -> 2996 | M26: [Ф] XBRL DepreciationDepletionAndAmortization (10-K/10-Q)
A27: Аренда самолётов (aircraft rent) | B27: $ млн | C27: 288 | D27: 198 | E27: 228 | F27: 252 | G27: 197 | H27: 193 | I27: 252 | J27: 118 | K27: 195 | L27: =I27+K27-J27 -> 329 | M27: [Ф] XBRL AircraftRental (10-K/10-Q)
A28: Специальные статьи (доход) в опер. расходах | B28: $ млн | C28: 246 | D28: -2616 | E28: -3367 | F28: 140 | G28: 949 | H28: 112 | I28: 259 | J28: 340 | K28: -534 | L28: =I28+K28-J28 -> -615 | M28: [Ф] Пресс-релизы 8-K по итогам 4 кв.: FY2019–2021 (8-K 19.01.2022), FY2022 (17.01.2023), FY2023 (22.01.2024), FY2024 (21.01.2025), FY2025 (20.01.2026); 1П — 8-K 15.07.2026; 2020–21 — гос. поддержка PSP (кредит)
A29: Участие сотрудников в прибыли (profit sharing) | B29: $ млн | C29: 485 | D29: 0 | E29: 0 | F29: 133 | G29: 681 | H29: 713 | I29: 704 | J29: 231 | K29: 150 | L29: =I29+K29-J29 -> 623 | M29: [Ф] Пресс-релизы 8-K по итогам 4 кв.: FY2019–2021 (8-K 19.01.2022), FY2022 (17.01.2023), FY2023 (22.01.2024), FY2024 (21.01.2025), FY2025 (20.01.2026); 1П — 8-K 15.07.2026; 2019 — [О] 0,17 цента × ASM из таблицы CASM-ex
A30: Операционная прибыль (GAAP) | B30: $ млн | C30: 4301 | D30: -6359 | E30: -1022 | F30: 2337 | G30: 4211 | H30: 5096 | I30: 4713 | J30: 1932 | K30: 2093 | L30: =I30+K30-J30 -> 4874 | M30: [Ф] XBRL OperatingIncomeLoss
A31: Скорр. операционная прибыль (non-GAAP) | B31: $ млн | C31: 4547 | D31: -8975 | E31: -4389 | F31: 2477 | G31: 5160 | H31: 5208 | I31: 4972 | J31: 2272 | K31: 1559 | L31: =I31+K31-J31 -> 4259 | M31: [Ф] Пресс-релизы 8-K по итогам 4 кв.: FY2019–2021 (8-K 19.01.2022), FY2022 (17.01.2023), FY2023 (22.01.2024), FY2024 (21.01.2025), FY2025 (20.01.2026); 1П — 8-K 15.07.2026
A32: Процентные расходы (валовые) | B32: $ млн | C32: 731 | D32: 1063 | E32: 1657 | F32: 1778 | G32: 1956 | H32: 1629 | I32: 1373 | J32: 717 | K32: 670 | L32: =I32+K32-J32 -> 1326 | M32: [Ф] Пресс-релизы 8-K по итогам 4 кв.: FY2019–2021 (8-K 19.01.2022), FY2022 (17.01.2023), FY2023 (22.01.2024), FY2024 (21.01.2025), FY2025 (20.01.2026); 1П — 8-K 15.07.2026
A33: Чистые процентные расходы (за вычетом капитализ. % и % доходов) | B33: $ млн | C33: 513 | D33: 942 | E33: 1541 | F33: 1375 | G33: 947 | H33: 676 | I33: 556 | J33: 288 | K33: 273 | L33: =I33+K33-J33 -> 541 | M33: [Ф] Пресс-релизы 8-K по итогам 4 кв.: FY2019–2021 (8-K 19.01.2022), FY2022 (17.01.2023), FY2023 (22.01.2024), FY2024 (21.01.2025), FY2025 (20.01.2026); 1П — 8-K 15.07.2026 (сверка Adj. EBITDA)
A34: Налог на прибыль | B34: $ млн | C34: 905 | D34: -1753 | E34: -593 | F34: 253 | G34: 769 | H34: 1019 | I34: 953 | J34: 366 | K34: 393 | L34: =I34+K34-J34 -> 980 | M34: [Ф] XBRL IncomeTaxExpenseBenefit
A35: Чистая прибыль (GAAP) | B35: $ млн | C35: 3009 | D35: -7069 | E35: -1964 | F35: 737 | G35: 2618 | H35: 3149 | I35: 3353 | J35: 1361 | K35: 1504 | L35: =I35+K35-J35 -> 3496 | M35: [Ф] XBRL NetIncomeLoss
... A37: Скорр. разводнённая прибыль на акцию | B37: $ | C37: 12.05 | D37: -27.57 | E37: -13.94 | F37: 2.52 | G37: 10.05 | H37: 10.61 | I37: 10.62 | J37: 4.75 | K37: 3.18 | L37: =I37+K37-J37 -> 9.05 | M37: [Ф] Пресс-релизы 8-K по итогам 4 кв.: FY2019–2021 (8-K 19.01.2022), FY2022 (17.01.2023), FY2023 (22.01.2024), FY2024 (21.01.2025), FY2025 (20.01.2026); 1П — 8-K 15.07.2026
A38: Разводнённое средневзв. число акций | B38: млн | C38: 259.9 | D38: 279.4 | E38: 321.9 | F38: 330.1 | G38: 331.9 | H38: 333.2 | I38: 328.5 | J38: 330.1 | K38: 326.7 | M38: [Ф] Пресс-релизы 8-K по итогам 4 кв.: FY2019–2021 (8-K 19.01.2022), FY2022 (17.01.2023), FY2023 (22.01.2024), FY2024 (21.01.2025), FY2025 (20.01.2026); 1П — 8-K 15.07.2026
A39: Скорр. EBITDA (non-GAAP, определение UAL) | B39: $ млн | C39: 6808 | D39: -6430 | E39: -1783 | F39: 4948 | G39: 7938 | H39: 8211 | I39: 8076 | J39: 3809 | K39: 3133 | L39: =I39+K39-J39 -> 7400 | M39: [Ф] Пресс-релизы 8-K по итогам 4 кв.: FY2019–2021 (8-K 19.01.2022), FY2022 (17.01.2023), FY2023 (22.01.2024), FY2024 (21.01.2025), FY2025 (20.01.2026); 1П — 8-K 15.07.2026
A40: Фиксированная часть операционной аренды (новое определение EBITDAR UAL) | B40: $ млн | H40: 855 | I40: 894 | J40: 433 | K40: 514 | L40: =I40+K40-J40 -> 975 | M40: [Ф] 8-K 20.01.2026 и 15.07.2026; ранее не раскрывалось
A41: Денежные потоки
A42: Операционный денежный поток (CFO) | B42: $ млн | C42: 6909 | D42: -4133 | E42: 2067 | F42: 6066 | G42: 6911 | H42: 9445 | I42: 8431 | J42: 5927 | K42: 6409 | L42: =I42+K42-J42 -> 8913 | M42: [Ф] XBRL NetCashProvidedByOperatingActivities
...

Sheet Metrics
A1: Производные метрики UAL (формулы на основе листа Hist)
A3: Метрика | B3: Ед. | C3: 2019 | D3: 2020 | E3: 2021 | F3: 2022 | G3: 2023 | H3: 2024 | I3: 2025 | J3: 1П25 | K3: 1П26 | L3: TTM 2К26 | M3: Источник / тип
A4: Операционные
A5: Загрузка (load factor) = RPM / ASM | B5: % | C5: =Hist!$C$6/Hist!$C$5 -> 0.8398626 | D5: =Hist!$D$6/Hist!$D$5 -> 0.6016335 | E5: =Hist!$E$6/Hist!$E$5 -> 0.72182736 | F5: =Hist!$F$6/Hist!$F$5 -> 0.83431239 | G5: =Hist!$G$6/Hist!$G$5 -> 0.8390227 | H5: =Hist!$H$6/Hist!$H$5 -> 0.83070521 | I5: =Hist!$I$6/Hist!$I$5 -> 0.82238013 | J5: =Hist!$J$6/Hist!$J$5 -> 0.81254898 | K5: =Hist!$K$6/Hist!$K$5 -> 0.82526655 | L5: =Hist!$L$6/Hist!$L$5 -> 0.82846872 | M5: формула
A6: Доходность (yield) = пасс. выручка / RPM | B6: центы | C6: =Hist!$C$16/Hist!$C$6*100 -> 16.554562 | D6: =Hist!$D$16/Hist!$D$6*100 -> 15.977965 | E6: =Hist!$E$16/Hist!$E$6*100 -> 15.659138 | F6: =Hist!$F$16/Hist!$F$6*100 -> 19.358676 | G6: =Hist!$G$16/Hist!$G$6*100 -> 20.065048 | H6: =Hist!$H$16/Hist!$H$6*100 -> 20.049671 | I6: =Hist!$I$16/Hist!$I$6*100 -> 19.673881 | J6: =Hist!$J$16/Hist!$J$6*100 -> 19.826549 | K6: =Hist!$K$16/Hist!$K$6*100 -> 21.496144 | L6: =Hist!$L$16/Hist!$L$6*100 -> 20.49467 | M6: формула
A7: PRASM = пасс. выручка / ASM | B7: центы | C7: =Hist!$C$16/Hist!$C$5*100 -> 13.903558 | D7: =Hist!$D$16/Hist!$D$5*100 -> 9.6128791 | E7: =Hist!$E$16/Hist!$E$5*100 -> 11.303194 | F7: =Hist!$F$16/Hist!$F$5*100 -> 16.151183 | G7: =Hist!$G$16/Hist!$G$5*100 -> 16.835031 | H7: =Hist!$H$16/Hist!$H$5*100 -> 16.655366 | I7: =Hist!$I$16/Hist!$I$5*100 -> 16.179409 | J7: =Hist!$J$16/Hist!$J$5*100 -> 16.110042 | K7: =Hist!$K$16/Hist!$K$5*100 -> 17.740049 | L7: =Hist!$L$16/Hist!$L$5*100 -> 16.979193 | M7: формула
A8: TRASM (RASM) = выручка / ASM | B8: центы | C8: =Hist!$C$19/Hist!$C$5*100 -> 15.17865 | D8: =Hist!$D$19/Hist!$D$5*100 -> 12.503664 | E8: =Hist!$E$19/Hist!$E$5*100 -> 13.786349 | F8: =Hist!$F$19/Hist!$F$5*100 -> 18.137401 | G8: =Hist!$G$19/Hist!$G$5*100 -> 18.438351 | H8: =Hist!$H$19/Hist!$H$5*100 -> 18.337323 | I8: =Hist!$I$19/Hist!$I$5*100 -> 17.884608 | J8: =Hist!$J$19/Hist!$J$5*100 -> 17.835401 | K8: =Hist!$K$19/Hist!$K$5*100 -> 19.566364 | L8: =Hist!$L$19/Hist!$L$5*100 -> 18.734327 | M8: формула
A9: CASM = опер. расходы / ASM | B9: центы | C9: =(Hist!$C$19-Hist!$C$30)/Hist!$C$5*100 -> 13.669522 | D9: =(Hist!$D$19-Hist!$D$30)/Hist!$D$5*100 -> 17.681834 | E9: =(Hist!$E$19-Hist!$E$30)/Hist!$E$5*100 -> 14.358309 | F9: =(Hist!$F$19-Hist!$F$30)/Hist!$F$5*100 -> 17.194523 | G9: =(Hist!$G$19-Hist!$G$30)/Hist!$G$5*100 -> 16.992926 | H9: =(Hist!$H$19-Hist!$H$30)/Hist!$H$5*100 -> 16.699712 | I9: =(Hist!$I$19-Hist!$I$30)/Hist!$I$5*100 -> 16.457655 | J9: =(Hist!$J$19-Hist!$J$30)/Hist!$J$5*100 -> 16.624139 | K9: =(Hist!$K$19-Hist!$K$30)/Hist!$K$5*100 -> 18.297702 | L9: =(Hist!$L$19-Hist!$L$30)/Hist!$L$5*100 -> 17.282686 | M9: формула
A10: CASM-ex (отчётный) | B10: центы | C10: =Hist!$C$8 -> 10.21 | D10: =Hist!$D$8 -> 17.13 | E10: =Hist!$E$8 -> 12.96 | F10: =Hist!$F$8 -> 11.73 | G10: =Hist!$G$8 -> 12.03 | H10: =Hist!$H$8 -> 12.58 | I10: =Hist!$I$8 -> 12.64 | J10: =Hist!$J$8 -> 12.74 | K10: =Hist!$K$8 -> 13.51 | M10: формула
A11: Топливо на ASM | B11: центы | C11: =Hist!$C$24/Hist!$C$5*100 -> 3.1414145 | D11: =Hist!$D$24/Hist!$D$5*100 -> 2.5675059 | E11: =Hist!$E$24/Hist!$E$5*100 -> 3.2207696 | F11: =Hist!$F$24/Hist!$F$5*100 -> 5.2905293 | G11: =Hist!$G$24/Hist!$G$5*100 -> 4.3424535 | H11: =Hist!$H$24/Hist!$H$5*100 -> 3.7778171 | I11: =Hist!$I$24/Hist!$I$5*100 -> 3.4503639 | J11: =Hist!$J$24/Hist!$J$5*100 -> 3.4331643 | K11: =Hist!$K$24/Hist!$K$5*100 -> 4.9400826 | L11: =Hist!$L$24/Hist!$L$5*100 -> 4.1905182 | M11: формула
A12: Спред TRASM − CASM | B12: центы | C12: =Metrics!$C$8-Metrics!$C$9 -> 1.5091281 | D12: =Metrics!$D$8-Metrics!$D$9 -> -5.1781701 | E12: =Metrics!$E$8-Metrics!$E$9 -> -0.57195944 | F12: =Metrics!$F$8-Metrics!$F$9 -> 0.94287858 | G12: =Metrics!$G$8-Metrics!$G$9 -> 1.445425 | H12: =Metrics!$H$8-Metrics!$H$9 -> 1.6376111 | I12: =Metrics!$I$8-Metrics!$I$9 -> 1.4269538 | J12: =Metrics!$J$8-Metrics!$J$9 -> 1.2112625 | K12: =Metrics!$K$8-Metrics!$K$9 -> 1.2686617 | L12: =Metrics!$L$8-Metrics!$L$9 -> 1.4516408 | M12: формула
A13: Топливная эффективность: галлонов на 1000 ASM | B13: галл. | C13: =Hist!$C$10/Hist!$C$5*1000 -> 15.059702 | D13: =Hist!$D$10/Hist!$D$5*1000 -> 16.318687 | E13: =Hist!$E$10/Hist!$E$5*1000 -> 15.272772 | F13: =Hist!$F$10/Hist!$F$5*1000 -> 14.556722 | G13: =Hist!$G$10/Hist!$G$5*1000 -> 14.433655 | H13: =Hist!$H$10/Hist!$H$5*1000 -> 14.280894 | I13: =Hist!$I$10/Hist!$I$5*1000 -> 14.118153 | J13: =Hist!$J$10/Hist!$J$5*1000 -> 14.131396 | K13: =Hist!$K$10/Hist!$K$5*1000 -> 14.014075 | L13: =Hist!$L$10/Hist!$L$5*1000 -> 14.060722 | M13: формула
A14: Производительность: ASM на сотрудника | B14: млн | C14: =Hist!$C$5/Hist!$C$12/1000 -> 2.9718352 | D14: =Hist!$D$5/Hist!$D$12/1000 -> 1.6505914 | E14: =Hist!$E$5/Hist!$E$12/1000 -> 2.1246611 | F14: =Hist!$F$5/Hist!$F$12/1000 -> 2.6708836 | G14: =Hist!$G$5/Hist!$G$12/1000 -> 2.8202614 | H14: =Hist!$H$5/Hist!$H$12/1000 -> 2.9001398 | I14: =Hist!$I$5/Hist!$I$12/1000 -> 2.9177032 | M14: формула
A15: Рост ASM г/г | B15: % | D15: =Hist!$D$5/Hist!$C$5-1 -> -0.56910726 | E15: =Hist!$E$5/Hist!$D$5-1 -> 0.45503404 | F15: =Hist!$F$5/Hist!$E$5-1 -> 0.38713035 | G15: =Hist!$G$5/Hist!$F$5-1 -> 0.17540285 | H15: =Hist!$H$5/Hist!$G$5-1 -> 0.068141954 | I15: =Hist!$I$5/Hist!$H$5-1 -> 0.061375066 | M15: формула
A16: Рост TRASM г/г | B16: % | D16: =Metrics!$D$8/Metrics!$C$8-1 -> -0.17623342 | E16: =Metrics!$E$8/Metrics!$D$8-1 -> 0.1025847 | F16: =Metrics!$F$8/Metrics!$E$8-1 -> 0.31560583 | G16: =Metrics!$G$8/Metrics!$F$8-1 -> 0.01659275 | H16: =Metrics!$H$8/Metrics!$G$8-1 -> -0.0054791863 | I16: =Metrics!$I$8/Metrics!$H$8-1 -> -0.024688175 | M16: формула
A17: Рост CASM-ex г/г | B17: % | D17: =Metrics!$D$10/Metrics!$C$10-1 -> 0.6777669 | E17: =Metrics!$E$10/Metrics!$D$10-1 -> -0.24343257 | F17: =Metrics!$F$10/Metrics!$E$10-1 -> -0.094907407 | G17: =Metrics!$G$10/Metrics!$F$10-1 -> 0.025575448 | H17: =Metrics!$H$10/Metrics!$G$10-1 -> 0.045719036 | I17: =Metrics!$I$10/Metrics!$H$10-1 -> 0.0047694754 | M17: формула
A18: Структура выручки
A19: Доля пассажирской выручки | B19: % | C19: =Hist!$C$16/Hist!$C$19 -> 0.91599436 | D19: =Hist!$D$16/Hist!$D$19 -> 0.76880495 | E19: =Hist!$E$16/Hist!$E$19 -> 0.81988309 | F19: =Hist!$F$16/Hist!$F$19 -> 0.89049049 | G19: =Hist!$G$16/Hist!$G$19 -> 0.91304429 | H19: =Hist!$H$16/Hist!$H$19 -> 0.90827682 | I19: =Hist!$I$16/Hist!$I$19 -> 0.90465549 | J19: =Hist!$J$16/Hist!$J$19 -> 0.90326209 | K19: =Hist!$K$16/Hist!$K$19 -> 0.90666047 | L19: =Hist!$L$16/Hist!$L$19 -> 0.90631458 | M19: формула
A20: Доля грузовой выручки | B20: % | C20: =Hist!$C$17/Hist!$C$19 -> 0.027254444 | D20: =Hist!$D$17/Hist!$D$19 -> 0.1073266 | E20: =Hist!$E$17/Hist!$E$19 -> 0.095356012 | F20: =Hist!$F$17/Hist!$F$19 -> 0.048292737 | G20: =Hist!$G$17/Hist!$G$19 -> 0.02783104 | H20: =Hist!$H$17/Hist!$H$19 -> 0.030545187 | I20: =Hist!$I$17/Hist!$I$19 -> 0.030116811 | J20: =Hist!$J$17/Hist!$J$19 -> 0.030195444 | K20: =Hist!$K$17/Hist!$K$19 -> 0.029399009 | L20: =Hist!$L$17/Hist!$L$19 -> 0.029712887 | M20: формула
A21: Доля прочей выручки | B21: % | C21: =Hist!$C$18/Hist!$C$19 -> 0.056751196 | D21: =Hist!$D$18/Hist!$D$19 -> 0.12386845 | E21: =Hist!$E$18/Hist!$E$19 -> 0.0847609 | F21: =Hist!$F$18/Hist!$F$19 -> 0.061216772 | G21: =Hist!$G$18/Hist!$G$19 -> 0.059124672 | H21: =Hist!$H$18/Hist!$H$19 -> 0.061177996 | I21: =Hist!$I$18/Hist!$I$19 -> 0.065227696 | J21: =Hist!$J$18/Hist!$J$19 -> 0.066542463 | K21: =Hist!$K$18/Hist!$K$19 -> 0.06394052 | L21: =Hist!$L$18/Hist!$L$19 -> 0.063972529 | M21: формула
A22: Партнёрская выручка MileagePlus / выручка | B22: % | G22: =Hist!$G$21/Hist!$G$19 -> 0.050263418 | H22: =Hist!$H$21/Hist!$H$19 -> 0.050821022 | I22: =Hist!$I$21/Hist!$I$19 -> 0.054173015 | J22: =Hist!$J$21/Hist!$J$19 -> 0.05624297 | K22: =Hist!$K$21/Hist!$K$19 -> 0.055762082 | L22: =Hist!$L$21/Hist!$L$19 -> 0.054052335 | M22: формула
A23: [О] MileagePlus всего ≈ партнёрская + погашения на перелёты | B23: $ млн | H23: =Hist!$H$21+Hist!$H$23 -> 6050 | I23: =Hist!$I$21+Hist!$I$23 -> 6614 | M23: [О] нижняя оценка: не включает продажу миль, учтённую при начислении
A24: [О] MileagePlus всего / выручка | B24: % | H24: =Metrics!$H$23/Hist!$H$19 -> 0.10602317 | I24: =Metrics!$I$23/Hist!$I$19 -> 0.11196885 | M24: формула
A25: Прибыльность
A26: Операционная маржа (GAAP) | B26: % | C26: =Hist!$C$30/Hist!$C$19 -> 0.099424397 | D26: =Hist!$D$30/Hist!$D$19 -> -0.4141322 | E26: =Hist!$E$30/Hist!$E$19 -> -0.041487375 | F26: =Hist!$F$30/Hist!$F$19 -> 0.051985319 | G26: =Hist!$G$30/Hist!$G$19 -> 0.078392315 | H26: =Hist!$H$30/Hist!$H$19 -> 0.089304803 | I26: =Hist!$I$30/Hist!$I$19 -> 0.079786694 | J26: =Hist!$J$30/Hist!$J$19 -> 0.067913386 | K26: =Hist!$K$30/Hist!$K$19 -> 0.06483891 | L26: =Hist!$L$30/Hist!$L$19 -> 0.077485613 | M26: формула
A27: Скорр. операционная маржа | B27: % | C27: =Hist!$C$31/Hist!$C$19 -> 0.10511108 | D27: =Hist!$D$31/Hist!$D$19 -> -0.58450016 | E27: =Hist!$E$31/Hist!$E$19 -> -0.17816839 | F27: =Hist!$F$31/Hist!$F$19 -> 0.055099544 | G27: =Hist!$G$31/Hist!$G$19 -> 0.096058976 | H27: =Hist!$H$31/Hist!$H$19 -> 0.091267546 | I27: =Hist!$I$31/Hist!$I$19 -> 0.084171322 | J27: =Hist!$J$31/Hist!$J$19 -> 0.079865017 | K27: =Hist!$K$31/Hist!$K$19 -> 0.048296159 | L27: =Hist!$L$31/Hist!$L$19 -> 0.067708499 | M27: формула
A28: Скорр. маржа до налога | B28: % | C28: =Hist!$C$36/Hist!$C$19 -> 0.094107585 | D28: =Hist!$D$36/Hist!$D$19 -> -0.64213611 | E28: =Hist!$E$36/Hist!$E$19 -> -0.23581229 | F28: =Hist!$F$36/Hist!$F$19 -> 0.024847069 | G28: =Hist!$G$36/Hist!$G$19 -> 0.080421468 | H28: =Hist!$H$36/Hist!$H$19 -> 0.080735328 | I28: =Hist!$I$36/Hist!$I$19 -> 0.077535128 | J28: =Hist!$J$36/Hist!$J$19 -> 0.072447975 | K28: =Hist!$K$36/Hist!$K$19 -> 0.04157373 | L28: =Hist!$L$36/Hist!$L$19 -> 0.061381196 | M28: формула
A29: Чистая маржа | B29: % | C29: =Hist!$C$35/Hist!$C$19 -> 0.06955778 | D29: =Hist!$D$35/Hist!$D$19 -> -0.46037121 | E29: =Hist!$E$35/Hist!$E$19 -> -0.079727206 | F29: =Hist!$F$35/Hist!$F$19 -> 0.016394172 | G29: =Hist!$G$35/Hist!$G$19 -> 0.048736899 | H29: =Hist!$H$35/Hist!$H$19 -> 0.055184621 | I29: =Hist!$I$35/Hist!$I$19 -> 0.056763162 | J29: =Hist!$J$35/Hist!$J$19 -> 0.047841676 | K29: =Hist!$K$35/Hist!$K$19 -> 0.046592317 | L29: =Hist!$L$35/Hist!$L$19 -> 0.055578519 | M29: формула
A30: EBITDAR = скорр. EBITDA + аренда самолётов (постоянное определение) | B30: $ млн | C30: =Hist!$C$39+Hist!$C$27 -> 7096 | D30: =Hist!$D$39+Hist!$D$27 -> -6232 | E30: =Hist!$E$39+Hist!$E$27 -> -1555 | F30: =Hist!$F$39+Hist!$F$27 -> 5200 | G30: =Hist!$G$39+Hist!$G$27 -> 8135 | H30: =Hist!$H$39+Hist!$H$27 -> 8404 | I30: =Hist!$I$39+Hist!$I$27 -> 8328 | J30: =Hist!$J$39+Hist!$J$27 -> 3927 | K30: =Hist!$K$39+Hist!$K$27 -> 3328 | L30: =Hist!$L$39+Hist!$L$27 -> 7729 | M30: формула; совпадает с отчётным EBITDAR UAL 2022–2024 (5,200 / 8,135 / 8,404)
A31: Справочно: EBITDAR по новому определению UAL (+ фикс. часть опер. аренды) | B31: $ млн | H31: =Hist!$H$39+Hist!$H$40 -> 9066 | I31: =Hist!$I$39+Hist!$I$40 -> 8970 | J31: =Hist!$J$39+Hist!$J$40 -> 4242 | K31: =Hist!$K$39+Hist!$K$40 -> 3647 | L31: =Hist!$L$39+Hist!$L$40 -> 8375 | M31: формула; TTM = 8,373 как в 8-K 15.07.2026
A32: Маржа EBITDAR | B32: % | C32: =Metrics!$C$30/Hist!$C$19 -> 0.16403523 | D32: =Metrics!$D$30/Hist!$D$19 -> -0.40586128 | E32: =Metrics!$E$30/Hist!$E$19 -> -0.063124137 | F32: =Metrics!$F$30/Hist!$F$19 -> 0.11567123 | G32: =Metrics!$G$30/Hist!$G$19 -> 0.15144182 | H32: =Metrics!$H$30/Hist!$H$19 -> 0.14727582 | I32: =Metrics!$I$30/Hist!$I$19 -> 0.14098527 | J32: =Metrics!$J$30/Hist!$J$19 -> 0.13804134 | K32: =Metrics!$K$30/Hist!$K$19 -> 0.10309789 | L32: =Metrics!$L$30/Hist!$L$19 -> 0.12287368 | M32: формула
A33: Денежный поток и качество прибыли
A34: FCF простой = CFO − капзатраты (GAAP) | B34: $ млн | C34: =Hist!$C$42-Hist!$C$43 -> 2381 | D34: =Hist!$D$42-Hist!$D$43 -> -5860 | E34: =Hist!$E$42-Hist!$E$43 -> -40 | F34: =Hist!$F$42-Hist!$F$43 -> 1247 | G34: =Hist!$G$42-Hist!$G$43 -> -260 | H34: =Hist!$H$42-Hist!$H$43 -> 3830 | I34: =Hist!$I$42-Hist!$I$43 -> 2557 | J34: =Hist!$J$42-Hist!$J$43 -> 3407 | K34: =Hist!$K$42-Hist!$K$43 -> 3394 | L34: =Hist!$L$42-Hist!$L$43 -> 2544 | M34: формула
A35: Маржа FCF | B35: % | C35: =Metrics!$C$34/Hist!$C$19 -> 0.05504057 | D35: =Metrics!$D$34/Hist!$D$19 -> -0.38163465 | E35: =Metrics!$E$34/Hist!$E$19 -> -0.001623772 | F35: =Metrics!$F$34/Hist!$F$19 -> 0.02773885 | G35: =Metrics!$G$34/Hist!$G$19 -> -0.0048401809 | H35: =Metrics!$H$34/Hist!$H$19 -> 0.067118799 | I35: =Metrics!$I$34/Hist!$I$19 -> 0.043287625 | J35: =Metrics!$J$34/Hist!$J$19 -> 0.11976237 | K35: =Metrics!$K$34/Hist!$K$19 -> 0.1051425 | L35: =Metrics!$L$34/Hist!$L$19 -> 0.040443865 | M35: формула
A36: CFO / чистая прибыль | B36: x | C36: =IF(Hist!$C$35>0,Hist!$C$42/Hist!$C$35,"н/п") -> 2.2961117 | D36: =IF(Hist!$D$35>0,Hist!$D$42/Hist!$D$35,"н/п") -> н/п | E36: =IF(Hist!$E$35>0,Hist!$E$42/Hist!$E$35,"н/п") -> н/п | F36: =IF(Hist!$F$35>0,Hist!$F$42/Hist!$F$35,"н/п") -> 8.2306649 | G36: =IF(Hist!$G$35>0,Hist!$G$42/Hist!$G$35,"н/п") -> 2.6398014 | H36: =IF(Hist!$H$35>0,Hist!$H$42/Hist!$H$35,"н/п") -> 2.9993649 | I36: =IF(Hist!$I$35>0,Hist!$I$42/Hist!$I$35,"н/п") -> 2.5144647 | J36: =IF(Hist!$J$35>0,Hist!$J$42/Hist!$J$35,"н/п") -> 4.3548861 | K36: =IF(Hist!$K$35>0,Hist!$K$42/Hist!$K$35,"н/п") -> 4.2613032 | L36: =IF(Hist!$L$35>0,Hist!$L$42/Hist!$L$35,"н/п") -> 2.5494851 | M36: формула
A37: Скорр. капзатраты / выручка | B37: % | D37: =Hist!$D$44/Hist!$D$19 -> 0.22461739 | E37: =Hist!$E$44/Hist!$E$19 -> 0.11800763 | F37: =Hist!$F$44/Hist!$F$19 -> 0.10761873 | G37: =Hist!$G$44/Hist!$G$19 -> 0.14796061 | H37: =Hist!$H$44/Hist!$H$19 -> 0.10975588 | I37: =Hist!$I$44/Hist!$I$19 -> 0.10607754 | J37: =Hist!$J$44/Hist!$J$19 -> 0.086754781 | K37: =Hist!$K$44/Hist!$K$19 -> 0.098110285 | L37: =Hist!$L$44/Hist!$L$19 -> 0.1107278 | M37: формула
A38: Изменение ATL + отложенной выручки MileagePlus (приток в CFO) | B38: $ млн | E38: =(Hist!$E$53+Hist!$E$54)-(Hist!$D$53+Hist!$D$54) -> 1828 | F38: =(Hist!$F$53+Hist!$F$54)-(Hist!$E$53+Hist!$E$54) -> 1594 | G38: =(Hist!$G$53+Hist!$G$54)-(Hist!$F$53+Hist!$F$54) -> -383 | H38: =(Hist!$H$53+Hist!$H$54)-(Hist!$G$53+Hist!$G$54) -> 1155 | I38: =(Hist!$I$53+Hist!$I$54)-(Hist!$H$53+Hist!$H$54) -> 906 | M38: формула
A39: CFO без прироста ATL и отложенной выручки | B39: $ млн | E39: =Hist!$E$42-Metrics!$E$38 -> 239 | F39: =Hist!$F$42-Metrics!$F$38 -> 4472 | G39: =Hist!$G$42-Metrics!$G$38 -> 7294 | H39: =Hist!$H$42-Metrics!$H$38 -> 8290 | I39: =Hist!$I$42-Metrics!$I$38 -> 7525 | M39: формула
A40: CFO без ATL / чистая прибыль | B40: x | F40: =IF(Hist!$F$35>0,Metrics!$F$39/Hist!$F$35,"н/п") -> 6.0678426 | G40: =IF(Hist!$G$35>0,Metrics!$G$39/Hist!$G$35,"н/п") -> 2.7860963 | H40: =IF(Hist!$H$35>0,Metrics!$H$39/Hist!$H$35,"н/п") -> 2.6325818 | I40: =IF(Hist!$I$35>0,Metrics!$I$39/Hist!$I$35,"н/п") -> 2.2442589 | M40: формула
A41: (ATL + отложенная выручка) / выручка | B41: % | D41: =(Hist!$D$53+Hist!$D$54)/Hist!$D$19 -> 0.70387496 | E41: =(Hist!$E$53+Hist!$E$54)/Hist!$E$19 -> 0.51294958 | F41: =(Hist!$F$53+Hist!$F$54)/Hist!$F$19 -> 0.31653876 | G41: =(Hist!$G$53+Hist!$G$54)/Hist!$G$19 -> 0.25777687 | H41: =(Hist!$H$53+Hist!$H$54)/Hist!$H$19 -> 0.26290241 | I41: =(Hist!$I$53+Hist!$I$54)/Hist!$I$19 -> 0.2693076 | M41: формула
...

Sheet Assumptions
A1: Допущения модели (все вводные прогноза — здесь)
A3: Параметр | B3: Ед. | C3: 2026E | D3: 2027E | E3: 2028E | F3: 2029E | G3: 2030E | H3: 2031E | I3: 2032E | J3: Обоснование / тип
A4: Рынок и оценка
A5: Цена акции UAL | B5: $ | C5: 103.23 | J5: [Ф] закрытие 13.10.2026, Yahoo Finance chart API (NASDAQ)
A6: Разводнённое число акций | B6: млн | C6: 326.6 | J6: [Ф] средневзвешенное разводнённое 2К26 (8-K 15.07.2026); базовое 324,6 млн на 09.07.2026
A7: Безрисковая ставка (UST 10 лет) | B7: % | C7: 0.0524 | J7: [Ф] FRED DGS10, 09.10.2026 = 5,24%
A8: Премия за риск рынка акций | B8: % | C8: 0.05 | J8: [Д] 5,0%: середина типичного диапазона 4,5–5,5% (Damodaran, implied ERP для США); не проверено на дату
A9: Стоимость долга до налога (вкл. аренду) | B9: % | C9: 0.065 | J9: [Д] UST10 5,24% + ~1,25 п.п. спред BB+/Ba1; проверка: ноты 2031 (5,375%) размещены 02.2026 при UST10 4,29% → спред ~1,1 п.п.
A10: Налоговая ставка | B10: % | C10: 0.22 | J10: [Д] эффективная ставка 2025 = 953/(3,353+953) = 22,1%; 1П26 = 20,7%
A11: PV налогового щита от убытков прошлых лет (NOL) | B11: $ млн | C11: 2000 | J11: [О] 10-K 2025: NOL $10,6 млрд (федеральные) → налоговый эффект $2,3 млрд вкл. штаты; использование за ~3–4 года, дисконт ~8,5% → ~$2,0 млрд
A12: FCFF 1П26 фактический (FCF UAL + чистые % после налога) | B12: $ млн | C12: =Hist!$K$45+Hist!$K$33*(1-Assumptions!$C$10) -> 3437.94 | J12: [О] 3,225 + 273×(1−t); вычитается из FCFF 2026E, т.к. дисконтируем с 30.06.2026
A13: Вес метода Гордона в итоговой DCF-оценке | B13: % | C13: 0.5 | J13: [Д] 50/50 Гордон и выходной мультипликатор
A14: Общие операционные параметры (все сценарии)
A15: Изменение расхода топлива на ASM (обновление парка) | B15: % | C15: -0.01 | D15: -0.01 | E15: -0.01 | F15: -0.01 | G15: -0.01 | H15: -0.01 | I15: -0.01 | J15: [Д] 2019→2025: 15,06→14,12 галл./1000 ASM = −1,1% в год (Metrics)
A16: Расходы на сторонние услуги (не в CASM-ex) | B16: % выручки | C16: 0.0045 | D16: 0.0045 | E16: 0.0045 | F16: 0.0045 | G16: 0.0045 | H16: 0.0045 | I16: 0.0045 | J16: [Д] 1П26: 132/32,280 = 0,41%
A17: Участие в прибыли | B17: % от EBIT до него | C17: 0.12 | D17: 0.12 | E17: 0.12 | F17: 0.12 | G17: 0.12 | H17: 0.12 | I17: 0.12 | J17: [Д] калибровка: 2025 704/(4,972+704) = 12,4%; 2024 12,0%
A18: D&A | B18: % выручки | C18: 0.048 | D18: 0.048 | E18: 0.048 | F18: 0.048 | G18: 0.048 | H18: 0.048 | I18: 0.048 | J18: [Д] TTM 2К26: 2,996/62,902 = 4,8%
A19: Фиксированная часть опер. аренды (для EBITDAR) | B19: % выручки | C19: 0.0155 | D19: 0.0155 | E19: 0.0155 | F19: 0.0155 | G19: 0.0155 | H19: 0.0155 | I19: 0.0155 | J19: [Д] TTM 2К26: 975/62,902 = 1,55%
A20: Ставка процента, заложенная в аренду | B20: % | C20: 0.065 | J20: [Д] = стоимость долга; часть арендного платежа, переносимая в финансирование
A21: Приток оборотного капитала (ATL, мили) | B21: % от прироста выручки | C21: 0.1 | D21: 0.1 | E21: 0.1 | F21: 0.1 | G21: 0.1 | H21: 0.1 | I21: 0.1 | J21: [Д] (ATL+отлож. выручка)/выручка = 27% (2025); с учётом оттоков по прочим статьям берём 10%
A22: Чистые процентные расходы (для EPS) | B22: $ млн | C22: 550 | D22: 550 | E22: 550 | F22: 550 | G22: 550 | H22: 550 | I22: 550 | J22: [Д] TTM 2К26 = 541 (8-K 15.07.2026)
A23: Скорр. капзатраты 2026E | B23: $ млн | C23: 7500 | J23: [Ф] прогноз UAL ~$7,5 млрд (Investor Update 15.07.2026)
A24: Терминальный рост (Гордон) | B24: % | C24: 0.025 | J24: [Д] ≈ номинальный рост ВВП США в долгосроке ниже текущей инфляции
A25: Доходность новых инвестиций в терминале (RONIC) | B25: % | C25: 0.1 | J25: [Д] чуть выше WACC: реинвестиции = g/RONIC = 25% NOPAT
A27: Сценарий: Пессимистичный (рецессия + дорогое топливо)
A28: Рост ASM | B28: % | C28: 0.025 | D28: -0.02 | E28: 0.02 | F28: 0.04 | G28: 0.04 | H28: 0.035 | I28: 0.03 | J28: [Д] см. логику базового сценария
A29: Базовый рост TRASM (без топлива) | B29: % | C29: 0.025 | D29: -0.05 | E29: 0.05 | F29: 0.045 | G29: 0.035 | H29: 0.027 | I29: 0.027 | J29: [Д] см. логику базового сценария
A30: Перенос топлива в тариф | B30: доля | C30: 0.8 | D30: 0.6 | E30: 1 | F30: 1 | G30: 1 | H30: 1 | I30: 1 | J30: [Д] см. логику базового сценария
A31: Рост CASM-ex | B31: % | C31: 0.055 | D31: 0.035 | E31: 0.01 | F31: 0.015 | G31: 0.02 | H31: 0.027 | I31: 0.027 | J31: [Д] см. логику базового сценария
A32: Цена топлива (all-in) | B32: $/галл. | C32: 3.97 | D32: 4.1 | E32: 3.4 | F32: 3.1 | G32: 3.1 | H32: 3.1 | I32: 3.1 | J32: [Д] см. логику базового сценария
A33: Скорр. капзатраты | B33: % выручки | D33: 0.08 | E33: 0.08 | F33: 0.09 | G33: 0.1 | H33: 0.1 | I33: 0.1 | J33: [Д] см. логику базового сценария
A34: Сценарий: Базовый
A35: Рост ASM | B35: % | C35: 0.025 | D35: 0.04 | E35: 0.05 | F35: 0.05 | G35: 0.045 | H35: 0.04 | I35: 0.035 | J35: [Д] 2026: 1П +3,4%, 2П ~+1,6% (прогноз UAL 0…+2%) (прогноз UAL 21.04.2026, сокращение из-за топлива); далее — поставки 787/MAX/A321 (10-Q: ожидаемые поставки)
A36: Базовый рост TRASM (без топлива) | B36: % | C36: 0.025 | D36: 0.02 | E36: 0.025 | F36: 0.025 | G36: 0.025 | H36: 0.025 | I36: 0.025 | J36: [Д] рост TRASM без переноса топлива; история 2019–2025: ~2,5% в год (TRASM 15,18→17,88, из них ~0,3 цента — топливо)
A37: Перенос топлива в тариф | B37: доля | C37: 0.8 | D37: 0.75 | E37: 1 | F37: 1 | G37: 1 | H37: 1 | I37: 1 | J37: [Д] доля изменения топливных затрат на ASM, переносимая в тариф; UAL: 1П ~50%, 3 кв. 80–90%, 4 кв. 100% (Investor Update 15.07.2026)
A38: Рост CASM-ex | B38: % | C38: 0.055 | D38: 0.025 | E38: 0.02 | F38: 0.023 | G38: 0.027 | H38: 0.027 | I38: 0.027 | J38: [Д] 2026: 1П +6,0% (сокращение мощностей, новые договоры AFA/IAM); 2027+ — инфляция зарплат против эффекта масштаба
A39: Цена топлива (all-in) | B39: $/галл. | C39: 3.97 | D39: 3.3 | E39: 3 | F39: 2.9 | G39: 2.9 | H39: 2.95 | I39: 3 | J39: [Д] 2026: 1П $3,53 факт, 2П ~$4,40 (спот Gulf Coast сент.–окт. $4,34–4,39 + ~$0,35 логистика/налоги); 2027 — EIA STEO окт. 2026 (Brent $84)
A40: Скорр. капзатраты | B40: % выручки | D40: 0.115 | E40: 0.12 | F40: 0.12 | G40: 0.11 | H40: 0.105 | I40: 0.1 | J40: [Д] 2026 — прогноз UAL $7,5 млрд; далее % выручки по контрактным обязательствам 10-K (2027–2030: $5,6–9,0 млрд в год только по заказам)
A41: Сценарий: Оптимистичный (премиальный спрос и маржа)
A42: Рост ASM | B42: % | C42: 0.025 | D42: 0.05 | E42: 0.06 | F42: 0.06 | G42: 0.05 | H42: 0.045 | I42: 0.04 | J42: [Д] см. логику базового сценария
...

Sheet Beta
A1: Бета UAL: месячные доходности против S&P 500, 60 месяцев (10.2021–10.2026)
A3: Месяц | B3: UAL (скорр. цена) | C3: S&P 500 | D3: Доходн. UAL | E3: Доходн. S&P | G3: Бета (SLOPE) | H3: =SLOPE(D5:D64,E5:E64) -> 1.3605204
A4: 2021-10 | B4: 46.14 | C4: 4605.38 | G4: Скорр. бета (Блюм) | H4: =0.67*H3+0.33 -> 1.2415487
A5: 2021-11 | B5: 42.26 | C5: 4567 | D5: =B5/B4-1 -> -0.084091894 | E5: =C5/C4-1 -> -0.0083337314
A6: 2021-12 | B6: 43.78 | C6: 4766.18 | D6: =B6/B5-1 -> 0.035967818 | E6: =C6/C5-1 -> 0.043612875 | G6: Источник: Yahoo Finance chart API, месячные цены закрытия (adjclose); последняя точка — 13.10.2026 (неполный месяц).
A7: 2022-01 | B7: 42.88 | C7: 4515.55 | D7: =B7/B6-1 -> -0.020557332 | E7: =C7/C6-1 -> -0.052585089 | G7: Для справки (тот же расчёт): DAL 1,42; AAL 1,44; LUV 1,23; ALK 1,42; JBLU 1,84 — медиана пиров 1,42.
A8: 2022-02 | B8: 44.4 | C8: 4373.94 | D8: =B8/B7-1 -> 0.035447761 | E8: =C8/C7-1 -> -0.031360521
A9: 2022-03 | B9: 46.36 | C9: 4530.41 | D9: =B9/B8-1 -> 0.044144144 | E9: =C9/C8-1 -> 0.035773239
A10: 2022-04 | B10: 50.5 | C10: 4131.93 | D10: =B10/B9-1 -> 0.089301122 | E10: =C10/C9-1 -> -0.087956719
A11: 2022-05 | B11: 47.63 | C11: 4132.15 | D11: =B11/B10-1 -> -0.056831683 | E11: =C11/C10-1 -> 5.3243884e-05
A12: 2022-06 | B12: 35.42 | C12: 3785.38 | D12: =B12/B11-1 -> -0.25635104 | E12: =C12/C11-1 -> -0.083919993
A13: 2022-07 | B13: 36.75 | C13: 4130.29 | D13: =B13/B12-1 -> 0.037549407 | E13: =C13/C12-1 -> 0.091116348
A14: 2022-08 | B14: 35.01 | C14: 3955 | D14: =B14/B13-1 -> -0.047346939 | E14: =C14/C13-1 -> -0.042440119
A15: 2022-09 | B15: 32.53 | C15: 3585.62 | D15: =B15/B14-1 -> -0.070836904 | E15: =C15/C14-1 -> -0.093395702
A16: 2022-10 | B16: 43.08 | C16: 3871.98 | D16: =B16/B15-1 -> 0.32431602 | E16: =C16/C15-1 -> 0.079863455
A17: 2022-11 | B17: 44.17 | C17: 4080.11 | D17: =B17/B16-1 -> 0.025301764 | E17: =C17/C16-1 -> 0.05375286
A18: 2022-12 | B18: 37.7 | C18: 3839.5 | D18: =B18/B17-1 -> -0.14647951 | E18: =C18/C17-1 -> -0.058971449
A19: 2023-01 | B19: 48.96 | C19: 4076.6 | D19: =B19/B18-1 -> 0.29867374 | E19: =C19/C18-1 -> 0.061752832
... A64: 2026-10 | B64: 103.23 | C64: 7805.45 | D64: =B64/B63-1 -> -0.069580892 | E64: =C64/C63-1 -> 0.020114905

Sheet WACC
A1: Ставка дисконтирования (WACC) с учётом аренды
A3: Компонент | B3: Ед. | C3: Значение | D3: Источник / тип
A4: Безрисковая ставка | B4: % | C4: =Assumptions!$C$7 -> 0.0524
A5: Бета (5 лет, месячная, сырая) | B5: x | C5: =Beta!$H$3 -> 1.3605204 | D5: лист Beta; скорр. по Блюму ~1,24 — ниже, даёт WACC ~8,2%
A6: Премия за риск | B6: % | C6: =Assumptions!$C$8 -> 0.05
A7: Стоимость собственного капитала = Rf + β × ERP | B7: % | C7: =WACC!$C$4+WACC!$C$5*WACC!$C$6 -> 0.12042602
A8: Стоимость долга до налога | B8: % | C8: =Assumptions!$C$9 -> 0.065
A9: Стоимость долга после налога | B9: % | C9: =WACC!$C$8*(1-Assumptions!$C$10) -> 0.0507
A10: Рыночная капитализация (цена × разводн. акции) | B10: $ млн | C10: =Assumptions!$C$5*Assumptions!$C$6 -> 33714.918
A11: Скорр. долг 30.06.2026 (долг + опер. аренда + пенсии) | B11: $ млн | C11: =Metrics!$K$43 -> 34742 | D11: Metrics; аренда включена в долг
A12: Доля собственного капитала | B12: % | C12: =WACC!$C$10/(WACC!$C$10+WACC!$C$11) -> 0.49249833
A13: Доля долга | B13: % | C13: =1-WACC!$C$12 -> 0.50750167
A14: WACC | B14: % | C14: =WACC!$C$12*WACC!$C$7+WACC!$C$13*WACC!$C$9 -> 0.085039949
A15: Чистый скорр. долг 30.06.2026 (вычитается из EV) | B15: $ млн | C15: =Metrics!$K$45 -> 18105

Sheet DCF
A1: DCF (FCFF) — три сценария, 2026E–2032E; дата оценки 30.06.2026 (баланс), середина периода
A3: Пессимистичный (рецессия + дорогое топливо) | B3: Ед. | C3: 2025A | D3: 2026E | E3: 2027E | F3: 2028E | G3: 2029E | H3: 2030E | I3: 2031E | J3: 2032E | K3: Источник / тип
A4: ASM | B4: млн | C4: =Hist!$I$5 -> 330284 | D4: =DCF!$C$4*(1+Assumptions!$C$28) -> 338541.1 | E4: =DCF!$D$4*(1+Assumptions!$D$28) -> 331770.28 | F4: =DCF!$E$4*(1+Assumptions!$E$28) -> 338405.68 | G4: =DCF!$F$4*(1+Assumptions!$F$28) -> 351941.91 | H4: =DCF!$G$4*(1+Assumptions!$G$28) -> 366019.59 | I4: =DCF!$H$4*(1+Assumptions!$H$28) -> 378830.27 | J4: =DCF!$I$4*(1+Assumptions!$I$28) -> 390195.18
A5: Галлонов на 1000 ASM | B5: галл. | C5: =Metrics!$I$13 -> 14.118153 | D5: =DCF!$C$5*(1+Assumptions!$C$15) -> 13.976971 | E5: =DCF!$D$5*(1+Assumptions!$D$15) -> 13.837202 | F5: =DCF!$E$5*(1+Assumptions!$E$15) -> 13.69883 | G5: =DCF!$F$5*(1+Assumptions!$F$15) -> 13.561841 | H5: =DCF!$G$5*(1+Assumptions!$G$15) -> 13.426223 | I5: =DCF!$H$5*(1+Assumptions!$H$15) -> 13.291961 | J5: =DCF!$I$5*(1+Assumptions!$I$15) -> 13.159041
A6: Цена топлива | B6: $/галл. | C6: =Hist!$I$9 -> 2.44 | D6: =Assumptions!$C$32 -> 3.97 | E6: =Assumptions!$D$32 -> 4.1 | F6: =Assumptions!$E$32 -> 3.4 | G6: =Assumptions!$F$32 -> 3.1 | H6: =Assumptions!$G$32 -> 3.1 | I6: =Assumptions!$H$32 -> 3.1 | J6: =Assumptions!$I$32 -> 3.1
A7: Топливо на ASM | B7: центы | C7: =DCF!$C$5*DCF!$C$6/10 -> 3.4448293 | D7: =DCF!$D$5*DCF!$D$6/10 -> 5.5488576 | E7: =DCF!$E$5*DCF!$E$6/10 -> 5.6732527 | F7: =DCF!$F$5*DCF!$F$6/10 -> 4.6576021 | G7: =DCF!$G$5*DCF!$G$6/10 -> 4.2041708 | H7: =DCF!$H$5*DCF!$H$6/10 -> 4.1621291 | I7: =DCF!$I$5*DCF!$I$6/10 -> 4.1205078 | J7: =DCF!$J$5*DCF!$J$6/10 -> 4.0793027
A8: TRASM = TRASM(t−1)×(1+базовый рост) + перенос×Δтопливо/ASM | B8: центы | C8: =Metrics!$I$8 -> 17.884608 | D8: =DCF!$C$8*(1+Assumptions!$C$29)+Assumptions!$C$30*(DCF!$D$7-DCF!$C$7) -> 20.014946 | E8: =DCF!$D$8*(1+Assumptions!$D$29)+Assumptions!$D$30*(DCF!$E$7-DCF!$D$7) -> 19.088836 | F8: =DCF!$E$8*(1+Assumptions!$E$29)+Assumptions!$E$30*(DCF!$F$7-DCF!$E$7) -> 19.027627 | G8: =DCF!$F$8*(1+Assumptions!$F$29)+Assumptions!$F$30*(DCF!$G$7-DCF!$F$7) -> 19.430439 | H8: =DCF!$G$8*(1+Assumptions!$G$29)+Assumptions!$G$30*(DCF!$H$7-DCF!$G$7) -> 20.068463 | I8: =DCF!$H$8*(1+Assumptions!$H$29)+Assumptions!$H$30*(DCF!$I$7-DCF!$H$7) -> 20.56869 | J8: =DCF!$I$8*(1+Assumptions!$I$29)+Assumptions!$I$30*(DCF!$J$7-DCF!$I$7) -> 21.08284
A9: Выручка | B9: $ млн | C9: =Hist!$I$19 -> 59070 | D9: =DCF!$D$4*DCF!$D$8/100 -> 67758.819 | E9: =DCF!$E$4*DCF!$E$8/100 -> 63331.084 | F9: =DCF!$F$4*DCF!$F$8/100 -> 64390.572 | G9: =DCF!$G$4*DCF!$G$8/100 -> 68383.859 | H9: =DCF!$H$4*DCF!$H$8/100 -> 73454.505 | I9: =DCF!$I$4*DCF!$I$8/100 -> 77920.424 | J9: =DCF!$J$4*DCF!$J$8/100 -> 82264.224
A10: CASM-ex | B10: центы | C10: =Metrics!$I$10 -> 12.64 | D10: =DCF!$C$10*(1+Assumptions!$C$31) -> 13.3352 | E10: =DCF!$D$10*(1+Assumptions!$D$31) -> 13.801932 | F10: =DCF!$E$10*(1+Assumptions!$E$31) -> 13.939951 | G10: =DCF!$F$10*(1+Assumptions!$F$31) -> 14.149051 | H10: =DCF!$G$10*(1+Assumptions!$G$31) -> 14.432032 | I10: =DCF!$H$10*(1+Assumptions!$H$31) -> 14.821696 | J10: =DCF!$I$10*(1+Assumptions!$I$31) -> 15.221882
A11: Нетопливные расходы (CASM-ex × ASM) | B11: $ млн | D11: =DCF!$D$4*DCF!$D$10/100 -> 45145.133 | E11: =DCF!$E$4*DCF!$E$10/100 -> 45790.708 | F11: =DCF!$F$4*DCF!$F$10/100 -> 47173.588 | G11: =DCF!$G$4*DCF!$G$10/100 -> 49796.439 | H11: =DCF!$H$4*DCF!$H$10/100 -> 52824.063 | I11: =DCF!$I$4*DCF!$I$10/100 -> 56149.073 | J11: =DCF!$J$4*DCF!$J$10/100 -> 59395.051
A12: Топливо | B12: $ млн | D12: =DCF!$D$4*DCF!$D$7/100 -> 18785.164 | E12: =DCF!$E$4*DCF!$E$7/100 -> 18822.166 | F12: =DCF!$F$4*DCF!$F$7/100 -> 15761.59 | G12: =DCF!$G$4*DCF!$G$7/100 -> 14796.239 | H12: =DCF!$H$4*DCF!$H$7/100 -> 15234.208 | I12: =DCF!$I$4*DCF!$I$7/100 -> 15609.731 | J12: =DCF!$J$4*DCF!$J$7/100 -> 15917.243
A13: Сторонние услуги | B13: $ млн | D13: =DCF!$D$9*Assumptions!$C$16 -> 304.91469 | E13: =DCF!$E$9*Assumptions!$D$16 -> 284.98988 | F13: =DCF!$F$9*Assumptions!$E$16 -> 289.75757 | G13: =DCF!$G$9*Assumptions!$F$16 -> 307.72736 | H13: =DCF!$H$9*Assumptions!$G$16 -> 330.54527 | I13: =DCF!$I$9*Assumptions!$H$16 -> 350.64191 | J13: =DCF!$J$9*Assumptions!$I$16 -> 370.18901
A14: EBIT до участия в прибыли | B14: $ млн | D14: =DCF!$D$9-DCF!$D$11-DCF!$D$12-DCF!$D$13 -> 3523.6082 | E14: =DCF!$E$9-DCF!$E$11-DCF!$E$12-DCF!$E$13 -> -1566.78 | F14: =DCF!$F$9-DCF!$F$11-DCF!$F$12-DCF!$F$13 -> 1165.6366 | G14: =DCF!$G$9-DCF!$G$11-DCF!$G$12-DCF!$G$13 -> 3483.4534 | H14: =DCF!$H$9-DCF!$H$11-DCF!$H$12-DCF!$H$13 -> 5065.6892 | I14: =DCF!$I$9-DCF!$I$11-DCF!$I$12-DCF!$I$13 -> 5810.9785 | J14: =DCF!$J$9-DCF!$J$11-DCF!$J$12-DCF!$J$13 -> 6581.7413
A15: Участие в прибыли | B15: $ млн | D15: =MAX(0,DCF!$D$14)*Assumptions!$C$17 -> 422.83298 | E15: =MAX(0,DCF!$E$14)*Assumptions!$D$17 -> 0 | F15: =MAX(0,DCF!$F$14)*Assumptions!$E$17 -> 139.87639 | G15: =MAX(0,DCF!$G$14)*Assumptions!$F$17 -> 418.0144 | H15: =MAX(0,DCF!$H$14)*Assumptions!$G$17 -> 607.8827 | I15: =MAX(0,DCF!$I$14)*Assumptions!$H$17 -> 697.31742 | J15: =MAX(0,DCF!$J$14)*Assumptions!$I$17 -> 789.80895
A16: Скорр. EBIT | B16: $ млн | C16: =Hist!$I$31 -> 4972 | D16: =DCF!$D$14-DCF!$D$15 -> 3100.7752 | E16: =DCF!$E$14-DCF!$E$15 -> -1566.78 | F16: =DCF!$F$14-DCF!$F$15 -> 1025.7602 | G16: =DCF!$G$14-DCF!$G$15 -> 3065.439 | H16: =DCF!$H$14-DCF!$H$15 -> 4457.8065 | I16: =DCF!$I$14-DCF!$I$15 -> 5113.6611 | J16: =DCF!$J$14-DCF!$J$15 -> 5791.9323
A17: Скорр. операционная маржа | B17: % | C17: =DCF!$C$16/DCF!$C$9 -> 0.084171322 | D17: =DCF!$D$16/DCF!$D$9 -> 0.045761943 | E17: =DCF!$E$16/DCF!$E$9 -> -0.02473951 | F17: =DCF!$F$16/DCF!$F$9 -> 0.015930286 | G17: =DCF!$G$16/DCF!$G$9 -> 0.044826937 | H17: =DCF!$H$16/DCF!$H$9 -> 0.060687993 | I17: =DCF!$I$16/DCF!$I$9 -> 0.06562671 | J17: =DCF!$J$16/DCF!$J$9 -> 0.070406454
A18: D&A | B18: $ млн | C18: =Hist!$I$26 -> 2939 | D18: =DCF!$D$9*Assumptions!$C$18 -> 3252.4233 | E18: =DCF!$E$9*Assumptions!$D$18 -> 3039.892 | F18: =DCF!$F$9*Assumptions!$E$18 -> 3090.7474 | G18: =DCF!$G$9*Assumptions!$F$18 -> 3282.4252 | H18: =DCF!$H$9*Assumptions!$G$18 -> 3525.8162 | I18: =DCF!$I$9*Assumptions!$H$18 -> 3740.1804 | J18: =DCF!$J$9*Assumptions!$I$18 -> 3948.6828
A19: EBITDAR = EBIT + D&A + фикс. аренда | B19: $ млн | C19: =Metrics!$I$31 -> 8970 | D19: =DCF!$D$16+DCF!$D$18+DCF!$D$9*Assumptions!$C$19 -> 7403.4602 | E19: =DCF!$E$16+DCF!$E$18+DCF!$E$9*Assumptions!$D$19 -> 2454.7439 | F19: =DCF!$F$16+DCF!$F$18+DCF!$F$9*Assumptions!$E$19 -> 5114.5615 | G19: =DCF!$G$16+DCF!$G$18+DCF!$G$9*Assumptions!$F$19 -> 7407.814 | H19: =DCF!$H$16+DCF!$H$18+DCF!$H$9*Assumptions!$G$19 -> 9122.1676 | I19: =DCF!$I$16+DCF!$I$18+DCF!$I$9*Assumptions!$H$19 -> 10061.608 | J19: =DCF!$J$16+DCF!$J$18+DCF!$J$9*Assumptions!$I$19 -> 11015.711
A20: Обязательства по опер. аренде | B20: $ млн | D20: =Hist!$K$51 -> 7204 | E20: =DCF!$D$20*(1+Assumptions!$D$28) -> 7059.92 | F20: =DCF!$E$20*(1+Assumptions!$E$28) -> 7201.1184 | G20: =DCF!$F$20*(1+Assumptions!$F$28) -> 7489.1631 | H20: =DCF!$G$20*(1+Assumptions!$G$28) -> 7788.7297 | I20: =DCF!$H$20*(1+Assumptions!$H$28) -> 8061.3352 | J20: =DCF!$I$20*(1+Assumptions!$I$28) -> 8303.1753
A21: Процентная часть аренды (возвращается в EBIT) | B21: $ млн | D21: =DCF!$D$20*Assumptions!$C$20 -> 468.26 | E21: =DCF!$E$20*Assumptions!$C$20 -> 458.8948 | F21: =DCF!$F$20*Assumptions!$C$20 -> 468.0727 | G21: =DCF!$G$20*Assumptions!$C$20 -> 486.7956 | H21: =DCF!$H$20*Assumptions!$C$20 -> 506.26743 | I21: =DCF!$I$20*Assumptions!$C$20 -> 523.98679 | J21: =DCF!$J$20*Assumptions!$C$20 -> 539.70639
A22: NOPAT (с поправкой на аренду) = (EBIT + % аренды) × (1 − t) | B22: $ млн | D22: =(DCF!$D$16+DCF!$D$21)*(1-Assumptions!$C$10) -> 2783.8474 | E22: =(DCF!$E$16+DCF!$E$21)*(1-Assumptions!$C$10) -> -864.15045 | F22: =(DCF!$F$16+DCF!$F$21)*(1-Assumptions!$C$10) -> 1165.1897 | G22: =(DCF!$G$16+DCF!$G$21)*(1-Assumptions!$C$10) -> 2770.743 | H22: =(DCF!$H$16+DCF!$H$21)*(1-Assumptions!$C$10) -> 3871.9777 | I22: =(DCF!$I$16+DCF!$I$21)*(1-Assumptions!$C$10) -> 4397.3653 | J22: =(DCF!$J$16+DCF!$J$21)*(1-Assumptions!$C$10) -> 4938.6782
A23: Скорр. капзатраты | B23: $ млн | D23: =Assumptions!$C$23 -> 7500 | E23: =DCF!$E$9*Assumptions!$D$33 -> 5066.4867 | F23: =DCF!$F$9*Assumptions!$E$33 -> 5151.2457 | G23: =DCF!$G$9*Assumptions!$F$33 -> 6154.5473 | H23: =DCF!$H$9*Assumptions!$G$33 -> 7345.4505 | I23: =DCF!$I$9*Assumptions!$H$33 -> 7792.0424 | J23: =DCF!$J$9*Assumptions!$I$33 -> 8226.4224
A24: Приток оборотного капитала | B24: $ млн | D24: =(DCF!$D$9-DCF!$C$9)*Assumptions!$C$21 -> 868.88192 | E24: =(DCF!$E$9-DCF!$D$9)*Assumptions!$D$21 -> -442.77351 | F24: =(DCF!$F$9-DCF!$E$9)*Assumptions!$E$21 -> 105.94876 | G24: =(DCF!$G$9-DCF!$F$9)*Assumptions!$F$21 -> 399.3287 | H24: =(DCF!$H$9-DCF!$G$9)*Assumptions!$G$21 -> 507.06459 | I24: =(DCF!$I$9-DCF!$H$9)*Assumptions!$H$21 -> 446.59198 | J24: =(DCF!$J$9-DCF!$I$9)*Assumptions!$I$21 -> 434.37995
A25: FCFF = NOPAT + D&A − капзатраты + Δоборотный капитал | B25: $ млн | D25: =DCF!$D$22+DCF!$D$18-DCF!$D$23+DCF!$D$24 -> -594.8473 | E25: =DCF!$E$22+DCF!$E$18-DCF!$E$23+DCF!$E$24 -> -3333.5186 | F25: =DCF!$F$22+DCF!$F$18-DCF!$F$23+DCF!$F$24 -> -789.35988 | G25: =DCF!$G$22+DCF!$G$18-DCF!$G$23+DCF!$G$24 -> 297.94958 | H25: =DCF!$H$22+DCF!$H$18-DCF!$H$23+DCF!$H$24 -> 559.40801 | I25: =DCF!$I$22+DCF!$I$18-DCF!$I$23+DCF!$I$24 -> 792.09523 | J25: =DCF!$J$22+DCF!$J$18-DCF!$J$23+DCF!$J$24 -> 1095.3185
A26: FCFF к дисконтированию (2026E — только 2П: минус факт 1П26) | B26: $ млн | D26: =DCF!$D$25-Assumptions!$C$12 -> -4032.7873 | E26: =DCF!$E$25 -> -3333.5186 | F26: =DCF!$F$25 -> -789.35988 | G26: =DCF!$G$25 -> 297.94958 | H26: =DCF!$H$25 -> 559.40801 | I26: =DCF!$I$25 -> 792.09523 | J26: =DCF!$J$25 -> 1095.3185
A27: Период дисконтирования (лет от 30.06.2026, середина периода) | B27: лет | D27: 0.25 | E27: 1 | F27: 2 | G27: 3 | H27: 4 | I27: 5 | J27: 6 | K27: [Д] середина периода; 2П26 = 0,25
A28: Коэффициент дисконтирования | B28: x | D28: =1/(1+WACC!$C$14)^DCF!$D$27 -> 0.97980256 | E28: =1/(1+WACC!$C$14)^DCF!$E$27 -> 0.92162505 | F28: =1/(1+WACC!$C$14)^DCF!$F$27 -> 0.84939274 | G28: =1/(1+WACC!$C$14)^DCF!$G$27 -> 0.78282163 | H28: =1/(1+WACC!$C$14)^DCF!$H$27 -> 0.72146802 | I28: =1/(1+WACC!$C$14)^DCF!$I$27 -> 0.664923 | J28: =1/(1+WACC!$C$14)^DCF!$J$27 -> 0.6128097
A29: PV FCFF | B29: $ млн | D29: =DCF!$D$26*DCF!$D$28 -> -3951.3353 | E29: =DCF!$E$26*DCF!$E$28 -> -3072.2543 | F29: =DCF!$F$26*DCF!$F$28 -> -670.47655 | G29: =DCF!$G$26*DCF!$G$28 -> 233.24138 | H29: =DCF!$H$26*DCF!$H$28 -> 403.59499 | I29: =DCF!$I$26*DCF!$I$28 -> 526.68234 | J29: =DCF!$J$26*DCF!$J$28 -> 671.2218
A30: EPS скорр. = (EBIT − чистые %) × (1 − t) / акции | B30: $ | D30: =(DCF!$D$16-Assumptions!$C$22)*(1-Assumptions!$C$10)/Assumptions!$C$6 -> 6.0918697 | E30: =(DCF!$E$16-Assumptions!$D$22)*(1-Assumptions!$C$10)/Assumptions!$C$6 -> -5.0553839 | F30: =(DCF!$F$16-Assumptions!$E$22)*(1-Assumptions!$C$10)/Assumptions!$C$6 -> 1.1362307 | G30: =(DCF!$G$16-Assumptions!$F$22)*(1-Assumptions!$C$10)/Assumptions!$C$6 -> 6.0074782 | H30: =(DCF!$H$16-Assumptions!$G$22)*(1-Assumptions!$C$10)/Assumptions!$C$6 -> 9.3327896 | I30: =(DCF!$I$16-Assumptions!$H$22)*(1-Assumptions!$C$10)/Assumptions!$C$6 -> 10.899129 | J30: =(DCF!$J$16-Assumptions!$I$22)*(1-Assumptions!$C$10)/Assumptions!$C$6 -> 12.519006
A31: Сумма PV FCFF 2П26–2032E | B31: $ млн | J31: =SUM(D29:J29) -> -5859.3256
A32: TV Гордон = NOPAT×(1+g)×(1−g/RONIC)/(WACC−g) | B32: $ млн | J32: =DCF!$J$22*(1+Assumptions!$C$24)*(1-Assumptions!$C$24/Assumptions!$C$25)/(WACC!$C$14-Assumptions!$C$24) -> 63234.712
A33: Выходной мультипликатор EV/EBITDAR | B33: x | J33: =Multiples!$C$51 -> 4.6083934 | K33: история UAL: мин / медиана / макс (лист Multiples)
A34: TV по мультипликатору = EV/EBITDAR × EBITDAR 2032E | B34: $ млн | J34: =DCF!$J$33*DCF!$J$19 -> 50764.727
A35: Дисконт TV (6,5 года) | B35: x | J35: =1/(1+WACC!$C$14)^6.5 -> 0.58830531
A36: EV (Гордон) | B36: $ млн | J36: =DCF!$J$31+DCF!$J$32*DCF!$J$35 -> 31341.991
A37: EV (мультипликатор) | B37: $ млн | J37: =DCF!$J$31+DCF!$J$34*DCF!$J$35 -> 24005.833
A38: Доля TV в EV (Гордон) | B38: % | J38: =DCF!$J$32*DCF!$J$35/DCF!$J$36 -> 1.1869481
A39: Стоимость акции (Гордон) = (EV − чистый скорр. долг + NOL) / акции | B39: $ | J39: =(DCF!$J$36-WACC!$C$15+Assumptions!$C$11)/Assumptions!$C$6 -> 46.653371
A40: Стоимость акции (мультипликатор) | B40: $ | J40: =(DCF!$J$37-WACC!$C$15+Assumptions!$C$11)/Assumptions!$C$6 -> 24.19116
A41: Стоимость акции DCF (взвешенная) | B41: $ | J41: =Assumptions!$C$13*DCF!$J$39+(1-Assumptions!$C$13)*DCF!$J$40 -> 35.422266
...

Sheet ReverseDCF
A1: Reverse DCF: какой рост RASM и какой WACC заложены в цену $103,23
A3: Поправка к базовому росту TRASM в 2027–2032 (п.п. в год) | C3: 2025A | D3: 2026E | E3: 2027E | F3: 2028E | G3: 2029E | H3: 2030E | I3: 2031E | J3: 2032E
A4: Поправки | B4: п.п. | D4: -0.01 | E4: -0.005 | F4: 0 | G4: 0.005 | H4: 0.01 | K4: [Д] сетка
A5: Базовый — reverse DCF | B5: Ед. | C5: 2025A | D5: 2026E | E5: 2027E | F5: 2028E | G5: 2029E | H5: 2030E | I5: 2031E | J5: 2032E | K5: Источник / тип
A6: ASM | B6: млн | C6: =Hist!$I$5 -> 330284 | D6: =ReverseDCF!$C$6*(1+Assumptions!$C$35) -> 338541.1 | E6: =ReverseDCF!$D$6*(1+Assumptions!$D$35) -> 352082.74 | F6: =ReverseDCF!$E$6*(1+Assumptions!$E$35) -> 369686.88 | G6: =ReverseDCF!$F$6*(1+Assumptions!$F$35) -> 388171.23 | H6: =ReverseDCF!$G$6*(1+Assumptions!$G$35) -> 405638.93 | I6: =ReverseDCF!$H$6*(1+Assumptions!$H$35) -> 421864.49 | J6: =ReverseDCF!$I$6*(1+Assumptions!$I$35) -> 436629.74
A7: Галлонов на 1000 ASM | B7: галл. | C7: =Metrics!$I$13 -> 14.118153 | D7: =ReverseDCF!$C$7*(1+Assumptions!$C$15) -> 13.976971 | E7: =ReverseDCF!$D$7*(1+Assumptions!$D$15) -> 13.837202 | F7: =ReverseDCF!$E$7*(1+Assumptions!$E$15) -> 13.69883 | G7: =ReverseDCF!$F$7*(1+Assumptions!$F$15) -> 13.561841 | H7: =ReverseDCF!$G$7*(1+Assumptions!$G$15) -> 13.426223 | I7: =ReverseDCF!$H$7*(1+Assumptions!$H$15) -> 13.291961 | J7: =ReverseDCF!$I$7*(1+Assumptions!$I$15) -> 13.159041
A8: Цена топлива | B8: $/галл. | C8: =Hist!$I$9 -> 2.44 | D8: =Assumptions!$C$39 -> 3.97 | E8: =Assumptions!$D$39 -> 3.3 | F8: =Assumptions!$E$39 -> 3 | G8: =Assumptions!$F$39 -> 2.9 | H8: =Assumptions!$G$39 -> 2.9 | I8: =Assumptions!$H$39 -> 2.95 | J8: =Assumptions!$I$39 -> 3
A9: Топливо на ASM | B9: центы | C9: =ReverseDCF!$C$7*ReverseDCF!$C$8/10 -> 3.4448293 | D9: =ReverseDCF!$D$7*ReverseDCF!$D$8/10 -> 5.5488576 | E9: =ReverseDCF!$E$7*ReverseDCF!$E$8/10 -> 4.5662765 | F9: =ReverseDCF!$F$7*ReverseDCF!$F$8/10 -> 4.1096489 | G9: =ReverseDCF!$G$7*ReverseDCF!$G$8/10 -> 3.932934 | H9: =ReverseDCF!$H$7*ReverseDCF!$H$8/10 -> 3.8936046 | I9: =ReverseDCF!$I$7*ReverseDCF!$I$8/10 -> 3.9211284 | J9: =ReverseDCF!$J$7*ReverseDCF!$J$8/10 -> 3.9477123
A10: TRASM = TRASM(t−1)×(1+базовый рост) + перенос×Δтопливо/ASM | B10: центы | C10: =Metrics!$I$8 -> 17.884608 | D10: =ReverseDCF!$C$10*(1+Assumptions!$C$36)+Assumptions!$C$37*(ReverseDCF!$D$9-ReverseDCF!$C$9) -> 20.014946 | E10: =ReverseDCF!$D$10*(1+Assumptions!$D$36+ReverseDCF!$D$4)+Assumptions!$D$37*(ReverseDCF!$E$9-ReverseDCF!$D$9) -> 19.47816 | F10: =ReverseDCF!$E$10*(1+Assumptions!$E$36+ReverseDCF!$D$4)+Assumptions!$E$37*(ReverseDCF!$F$9-ReverseDCF!$E$9) -> 19.313705 | G10: =ReverseDCF!$F$10*(1+Assumptions!$F$36+ReverseDCF!$D$4)+Assumptions!$F$37*(ReverseDCF!$G$9-ReverseDCF!$F$9) -> 19.426695 | H10: =ReverseDCF!$G$10*(1+Assumptions!$G$36+ReverseDCF!$D$4)+Assumptions!$G$37*(ReverseDCF!$H$9-ReverseDCF!$G$9) -> 19.678766 | I10: =ReverseDCF!$H$10*(1+Assumptions!$H$36+ReverseDCF!$D$4)+Assumptions!$H$37*(ReverseDCF!$I$9-ReverseDCF!$H$9) -> 20.001472 | J10: =ReverseDCF!$I$10*(1+Assumptions!$I$36+ReverseDCF!$D$4)+Assumptions!$I$37*(ReverseDCF!$J$9-ReverseDCF!$I$9) -> 20.328078
A11: Выручка | B11: $ млн | C11: =Hist!$I$19 -> 59070 | D11: =ReverseDCF!$D$6*ReverseDCF!$D$10/100 -> 67758.819 | E11: =ReverseDCF!$E$6*ReverseDCF!$E$10/100 -> 68579.24 | F11: =ReverseDCF!$F$6*ReverseDCF!$F$10/100 -> 71400.232 | G11: =ReverseDCF!$G$6*ReverseDCF!$G$10/100 -> 75408.841 | H11: =ReverseDCF!$H$6*ReverseDCF!$H$10/100 -> 79824.738 | I11: =ReverseDCF!$I$6*ReverseDCF!$I$10/100 -> 84379.106 | J11: =ReverseDCF!$J$6*ReverseDCF!$J$10/100 -> 88758.434
A12: CASM-ex | B12: центы | C12: =Metrics!$I$10 -> 12.64 | D12: =ReverseDCF!$C$12*(1+Assumptions!$C$38) -> 13.3352 | E12: =ReverseDCF!$D$12*(1+Assumptions!$D$38) -> 13.66858 | F12: =ReverseDCF!$E$12*(1+Assumptions!$E$38) -> 13.941952 | G12: =ReverseDCF!$F$12*(1+Assumptions!$F$38) -> 14.262616 | H12: =ReverseDCF!$G$12*(1+Assumptions!$G$38) -> 14.647707 | I12: =ReverseDCF!$H$12*(1+Assumptions!$H$38) -> 15.043195 | J12: =ReverseDCF!$I$12*(1+Assumptions!$I$38) -> 15.449361
A13: Нетопливные расходы (CASM-ex × ASM) | B13: $ млн | D13: =ReverseDCF!$D$6*ReverseDCF!$D$12/100 -> 45145.133 | E13: =ReverseDCF!$E$6*ReverseDCF!$E$12/100 -> 48124.712 | F13: =ReverseDCF!$F$6*ReverseDCF!$F$12/100 -> 51541.566 | G13: =ReverseDCF!$G$6*ReverseDCF!$G$12/100 -> 55363.373 | H13: =ReverseDCF!$H$6*ReverseDCF!$H$12/100 -> 59416.803 | I13: =ReverseDCF!$I$6*ReverseDCF!$I$12/100 -> 63461.898 | J13: =ReverseDCF!$J$6*ReverseDCF!$J$12/100 -> 67456.508
A14: Топливо | B14: $ млн | D14: =ReverseDCF!$D$6*ReverseDCF!$D$9/100 -> 18785.164 | E14: =ReverseDCF!$E$6*ReverseDCF!$E$9/100 -> 16077.072 | F14: =ReverseDCF!$F$6*ReverseDCF!$F$9/100 -> 15192.833 | G14: =ReverseDCF!$G$6*ReverseDCF!$G$9/100 -> 15266.518 | H14: =ReverseDCF!$H$6*ReverseDCF!$H$9/100 -> 15793.976 | I14: =ReverseDCF!$I$6*ReverseDCF!$I$9/100 -> 16541.848 | J14: =ReverseDCF!$J$6*ReverseDCF!$J$9/100 -> 17236.886
A15: Сторонние услуги | B15: $ млн | D15: =ReverseDCF!$D$11*Assumptions!$C$16 -> 304.91469 | E15: =ReverseDCF!$E$11*Assumptions!$D$16 -> 308.60658 | F15: =ReverseDCF!$F$11*Assumptions!$E$16 -> 321.30105 | G15: =ReverseDCF!$G$11*Assumptions!$F$16 -> 339.33979 | H15: =ReverseDCF!$H$11*Assumptions!$G$16 -> 359.21132 | I15: =ReverseDCF!$I$11*Assumptions!$H$16 -> 379.70598 | J15: =ReverseDCF!$J$11*Assumptions!$I$16 -> 399.41295
A16: EBIT до участия в прибыли | B16: $ млн | D16: =ReverseDCF!$D$11-ReverseDCF!$D$13-ReverseDCF!$D$14-ReverseDCF!$D$15 -> 3523.6082 | E16: =ReverseDCF!$E$11-ReverseDCF!$E$13-ReverseDCF!$E$14-ReverseDCF!$E$15 -> 4068.8501 | F16: =ReverseDCF!$F$11-ReverseDCF!$F$13-ReverseDCF!$F$14-ReverseDCF!$F$15 -> 4344.5325 | G16: =ReverseDCF!$G$11-ReverseDCF!$G$13-ReverseDCF!$G$14-ReverseDCF!$G$15 -> 4439.6103 | H16: =ReverseDCF!$H$11-ReverseDCF!$H$13-ReverseDCF!$H$14-ReverseDCF!$H$15 -> 4254.7475 | I16: =ReverseDCF!$I$11-ReverseDCF!$I$13-ReverseDCF!$I$14-ReverseDCF!$I$15 -> 3995.6533 | J16: =ReverseDCF!$J$11-ReverseDCF!$J$13-ReverseDCF!$J$14-ReverseDCF!$J$15 -> 3665.6268
A17: Участие в прибыли | B17: $ млн | D17: =MAX(0,ReverseDCF!$D$16)*Assumptions!$C$17 -> 422.83298 | E17: =MAX(0,ReverseDCF!$E$16)*Assumptions!$D$17 -> 488.26201 | F17: =MAX(0,ReverseDCF!$F$16)*Assumptions!$E$17 -> 521.3439 | G17: =MAX(0,ReverseDCF!$G$16)*Assumptions!$F$17 -> 532.75324 | H17: =MAX(0,ReverseDCF!$H$16)*Assumptions!$G$17 -> 510.5697 | I17: =MAX(0,ReverseDCF!$I$16)*Assumptions!$H$17 -> 479.4784 | J17: =MAX(0,ReverseDCF!$J$16)*Assumptions!$I$17 -> 439.87522
A18: Скорр. EBIT | B18: $ млн | C18: =Hist!$I$31 -> 4972 | D18: =ReverseDCF!$D$16-ReverseDCF!$D$17 -> 3100.7752 | E18: =ReverseDCF!$E$16-ReverseDCF!$E$17 -> 3580.5881 | F18: =ReverseDCF!$F$16-ReverseDCF!$F$17 -> 3823.1886 | G18: =ReverseDCF!$G$16-ReverseDCF!$G$17 -> 3906.8571 | H18: =ReverseDCF!$H$16-ReverseDCF!$H$17 -> 3744.1778 | I18: =ReverseDCF!$I$16-ReverseDCF!$I$17 -> 3516.1749 | J18: =ReverseDCF!$J$16-ReverseDCF!$J$17 -> 3225.7516
A19: Скорр. операционная маржа | B19: % | C19: =ReverseDCF!$C$18/ReverseDCF!$C$11 -> 0.084171322 | D19: =ReverseDCF!$D$18/ReverseDCF!$D$11 -> 0.045761943 | E19: =ReverseDCF!$E$18/ReverseDCF!$E$11 -> 0.052210962 | F19: =ReverseDCF!$F$18/ReverseDCF!$F$11 -> 0.053545885 | G19: =ReverseDCF!$G$18/ReverseDCF!$G$11 -> 0.051809005 | H19: =ReverseDCF!$H$18/ReverseDCF!$H$11 -> 0.046904981 | I19: =ReverseDCF!$I$18/ReverseDCF!$I$11 -> 0.041671156 | J19: =ReverseDCF!$J$18/ReverseDCF!$J$11 -> 0.036343043
A20: D&A | B20: $ млн | C20: =Hist!$I$26 -> 2939 | D20: =ReverseDCF!$D$11*Assumptions!$C$18 -> 3252.4233 | E20: =ReverseDCF!$E$11*Assumptions!$D$18 -> 3291.8035 | F20: =ReverseDCF!$F$11*Assumptions!$E$18 -> 3427.2112 | G20: =ReverseDCF!$G$11*Assumptions!$F$18 -> 3619.6244 | H20: =ReverseDCF!$H$11*Assumptions!$G$18 -> 3831.5874 | I20: =ReverseDCF!$I$11*Assumptions!$H$18 -> 4050.1971 | J20: =ReverseDCF!$J$11*Assumptions!$I$18 -> 4260.4048
A21: EBITDAR = EBIT + D&A + фикс. аренда | B21: $ млн | C21: =Metrics!$I$31 -> 8970 | D21: =ReverseDCF!$D$18+ReverseDCF!$D$20+ReverseDCF!$D$11*Assumptions!$C$19 -> 7403.4602 | E21: =ReverseDCF!$E$18+ReverseDCF!$E$20+ReverseDCF!$E$11*Assumptions!$D$19 -> 7935.3698 | F21: =ReverseDCF!$F$18+ReverseDCF!$F$20+ReverseDCF!$F$11*Assumptions!$E$19 -> 8357.1034 | G21: =ReverseDCF!$G$18+ReverseDCF!$G$20+ReverseDCF!$G$11*Assumptions!$F$19 -> 8695.3185 | H21: =ReverseDCF!$H$18+ReverseDCF!$H$20+ReverseDCF!$H$11*Assumptions!$G$19 -> 8813.0487 | I21: =ReverseDCF!$I$18+ReverseDCF!$I$20+ReverseDCF!$I$11*Assumptions!$H$19 -> 8874.2482 | J21: =ReverseDCF!$J$18+ReverseDCF!$J$20+ReverseDCF!$J$11*Assumptions!$I$19 -> 8861.9121
